[Sat Jul 05 06:04:48.356758 2014] [authz_core:error] [pid 10210] [client 78.185.84.34:23252] AH01630: client denied by server configuration: /home/talehouse.wsgi
[Sat Jul 05 06:04:48.914438 2014] [authz_core:error] [pid 10210] [client 78.185.84.34:23252] AH01630: client denied by server configuration: /home/talehouse.wsgi
[Sat Jul 05 06:04:51.042472 2014] [authz_core:error] [pid 10210] [client 78.185.84.34:23252] AH01630: client denied by server configuration: /home/talehouse.wsgi
[Sat Jul 05 06:04:51.431477 2014] [authz_core:error] [pid 10210] [client 78.185.84.34:23252] AH01630: client denied by server configuration: /home/talehouse.wsgi
[Sat Jul 05 06:04:53.220437 2014] [authz_core:error] [pid 10210] [client 78.185.84.34:23252] AH01630: client denied by server configuration: /home/talehouse.wsgi
[Sat Jul 05 06:04:53.599514 2014] [authz_core:error] [pid 10210] [client 78.185.84.34:23252] AH01630: client denied by server configuration: /home/talehouse.wsgi
[Sat Jul 05 06:09:38.754474 2014] [:error] [pid 10278] [client 78.185.84.34:23475] mod_wsgi (pid=10278): Target WSGI script '/home/talehouse.wsgi' cannot be loaded as Python module.
[Sat Jul 05 06:09:38.754546 2014] [:error] [pid 10278] [client 78.185.84.34:23475] mod_wsgi (pid=10278): Exception occurred processing WSGI script '/home/talehouse.wsgi'.
[Sat Jul 05 06:09:38.754630 2014] [:error] [pid 10278] [client 78.185.84.34:23475] Traceback (most recent call last):
[Sat Jul 05 06:09:38.754684 2014] [:error] [pid 10278] [client 78.185.84.34:23475]   File "/home/talehouse.wsgi", line 5, in <module>
[Sat Jul 05 06:09:38.755562 2014] [:error] [pid 10278] [client 78.185.84.34:23475]     import django.core.handlers.wsgi
[Sat Jul 05 06:09:38.755596 2014] [:error] [pid 10278] [client 78.185.84.34:23475] ImportError: No module named django.core.handlers.wsgi
[Sat Jul 05 06:09:39.288638 2014] [:error] [pid 10277] [client 78.185.84.34:23474] mod_wsgi (pid=10277): Target WSGI script '/home/talehouse.wsgi' cannot be loaded as Python module.
[Sat Jul 05 06:09:39.288695 2014] [:error] [pid 10277] [client 78.185.84.34:23474] mod_wsgi (pid=10277): Exception occurred processing WSGI script '/home/talehouse.wsgi'.
[Sat Jul 05 06:09:39.288717 2014] [:error] [pid 10277] [client 78.185.84.34:23474] Traceback (most recent call last):
[Sat Jul 05 06:09:39.288752 2014] [:error] [pid 10277] [client 78.185.84.34:23474]   File "/home/talehouse.wsgi", line 5, in <module>
[Sat Jul 05 06:09:39.288829 2014] [:error] [pid 10277] [client 78.185.84.34:23474]     import django.core.handlers.wsgi
[Sat Jul 05 06:09:39.288855 2014] [:error] [pid 10277] [client 78.185.84.34:23474] ImportError: No module named django.core.handlers.wsgi
[Sat Jul 05 06:16:55.397268 2014] [:error] [pid 10330] [remote 78.185.84.34:43866] mod_wsgi (pid=10330): Target WSGI script '/home/talehouse.wsgi' cannot be loaded as Python module.
[Sat Jul 05 06:16:55.397359 2014] [:error] [pid 10330] [remote 78.185.84.34:43866] mod_wsgi (pid=10330): Exception occurred processing WSGI script '/home/talehouse.wsgi'.
[Sat Jul 05 06:16:55.397384 2014] [:error] [pid 10330] [remote 78.185.84.34:43866] Traceback (most recent call last):
[Sat Jul 05 06:16:55.397411 2014] [:error] [pid 10330] [remote 78.185.84.34:43866]   File "/home/talehouse.wsgi", line 5, in <module>
[Sat Jul 05 06:16:55.397484 2014] [:error] [pid 10330] [remote 78.185.84.34:43866]     import django.core.handlers.wsgi
[Sat Jul 05 06:16:55.397509 2014] [:error] [pid 10330] [remote 78.185.84.34:43866] ImportError: No module named django.core.handlers.wsgi
[Sat Jul 05 06:16:55.938922 2014] [:error] [pid 10330] [remote 78.185.84.34:16712] mod_wsgi (pid=10330): Target WSGI script '/home/talehouse.wsgi' cannot be loaded as Python module.
[Sat Jul 05 06:16:55.938962 2014] [:error] [pid 10330] [remote 78.185.84.34:16712] mod_wsgi (pid=10330): Exception occurred processing WSGI script '/home/talehouse.wsgi'.
[Sat Jul 05 06:16:55.938993 2014] [:error] [pid 10330] [remote 78.185.84.34:16712] Traceback (most recent call last):
[Sat Jul 05 06:16:55.939027 2014] [:error] [pid 10330] [remote 78.185.84.34:16712]   File "/home/talehouse.wsgi", line 5, in <module>
[Sat Jul 05 06:16:55.939082 2014] [:error] [pid 10330] [remote 78.185.84.34:16712]     import django.core.handlers.wsgi
[Sat Jul 05 06:16:55.939112 2014] [:error] [pid 10330] [remote 78.185.84.34:16712] ImportError: No module named django.core.handlers.wsgi
[Sat Jul 05 06:56:05.364616 2014] [:error] [pid 10808] [client 78.185.112.9:10509] mod_wsgi (pid=10808): Target WSGI script '/home/talehouse.wsgi' cannot be loaded as Python module.
[Sat Jul 05 06:56:05.365640 2014] [:error] [pid 10808] [client 78.185.112.9:10509] mod_wsgi (pid=10808): Exception occurred processing WSGI script '/home/talehouse.wsgi'.
[Sat Jul 05 06:56:05.365673 2014] [:error] [pid 10808] [client 78.185.112.9:10509] Traceback (most recent call last):
[Sat Jul 05 06:56:05.365704 2014] [:error] [pid 10808] [client 78.185.112.9:10509]   File "/home/talehouse.wsgi", line 5, in <module>
[Sat Jul 05 06:56:05.365786 2014] [:error] [pid 10808] [client 78.185.112.9:10509]     import django.core.handlers.wsgi
[Sat Jul 05 06:56:05.365811 2014] [:error] [pid 10808] [client 78.185.112.9:10509] ImportError: No module named django.core.handlers.wsgi
[Sat Jul 05 06:56:05.908599 2014] [:error] [pid 10807] [client 78.185.112.9:10508] mod_wsgi (pid=10807): Target WSGI script '/home/talehouse.wsgi' cannot be loaded as Python module.
[Sat Jul 05 06:56:05.908651 2014] [:error] [pid 10807] [client 78.185.112.9:10508] mod_wsgi (pid=10807): Exception occurred processing WSGI script '/home/talehouse.wsgi'.
[Sat Jul 05 06:56:05.908672 2014] [:error] [pid 10807] [client 78.185.112.9:10508] Traceback (most recent call last):
[Sat Jul 05 06:56:05.908700 2014] [:error] [pid 10807] [client 78.185.112.9:10508]   File "/home/talehouse.wsgi", line 5, in <module>
[Sat Jul 05 06:56:05.908773 2014] [:error] [pid 10807] [client 78.185.112.9:10508]     import django.core.handlers.wsgi
[Sat Jul 05 06:56:05.908798 2014] [:error] [pid 10807] [client 78.185.112.9:10508] ImportError: No module named django.core.handlers.wsgi
[Sat Jul 05 07:06:25.737423 2014] [:error] [pid 12053] [client 78.185.112.9:10984] mod_wsgi (pid=12053): Target WSGI script '/home/talehouse.wsgi' cannot be loaded as Python module.
[Sat Jul 05 07:06:25.737517 2014] [:error] [pid 12053] [client 78.185.112.9:10984] mod_wsgi (pid=12053): Exception occurred processing WSGI script '/home/talehouse.wsgi'.
[Sat Jul 05 07:06:25.737596 2014] [:error] [pid 12053] [client 78.185.112.9:10984] Traceback (most recent call last):
[Sat Jul 05 07:06:25.737678 2014] [:error] [pid 12053] [client 78.185.112.9:10984]   File "/home/talehouse.wsgi", line 5, in <module>
[Sat Jul 05 07:06:25.737842 2014] [:error] [pid 12053] [client 78.185.112.9:10984]     import django.core.handlers.wsgi
[Sat Jul 05 07:06:25.737893 2014] [:error] [pid 12053] [client 78.185.112.9:10984] ImportError: No module named django.core.handlers.wsgi
[Sat Jul 05 07:06:26.287252 2014] [:error] [pid 12052] [client 78.185.112.9:10983] mod_wsgi (pid=12052): Target WSGI script '/home/talehouse.wsgi' cannot be loaded as Python module.
[Sat Jul 05 07:06:26.287311 2014] [:error] [pid 12052] [client 78.185.112.9:10983] mod_wsgi (pid=12052): Exception occurred processing WSGI script '/home/talehouse.wsgi'.
[Sat Jul 05 07:06:26.287338 2014] [:error] [pid 12052] [client 78.185.112.9:10983] Traceback (most recent call last):
[Sat Jul 05 07:06:26.287367 2014] [:error] [pid 12052] [client 78.185.112.9:10983]   File "/home/talehouse.wsgi", line 5, in <module>
[Sat Jul 05 07:06:26.287440 2014] [:error] [pid 12052] [client 78.185.112.9:10983]     import django.core.handlers.wsgi
[Sat Jul 05 07:06:26.287466 2014] [:error] [pid 12052] [client 78.185.112.9:10983] ImportError: No module named django.core.handlers.wsgi
[Sat Jul 05 07:12:00.750381 2014] [:error] [pid 12120] [client 78.185.112.9:11032] mod_wsgi (pid=12120): Target WSGI script '/home/talehouse.wsgi' cannot be loaded as Python module.
[Sat Jul 05 07:12:00.750447 2014] [:error] [pid 12120] [client 78.185.112.9:11032] mod_wsgi (pid=12120): Exception occurred processing WSGI script '/home/talehouse.wsgi'.
[Sat Jul 05 07:12:00.750483 2014] [:error] [pid 12120] [client 78.185.112.9:11032] Traceback (most recent call last):
[Sat Jul 05 07:12:00.750522 2014] [:error] [pid 12120] [client 78.185.112.9:11032]   File "/home/talehouse.wsgi", line 13, in <module>
[Sat Jul 05 07:12:00.750658 2014] [:error] [pid 12120] [client 78.185.112.9:11032]     execfile(activate_env, dict(__file__=activate_env))
[Sat Jul 05 07:12:00.750688 2014] [:error] [pid 12120] [client 78.185.112.9:11032] IOError: [Errno 13] Permission denied: '/root/env/bin/activate_this.py'
[Sat Jul 05 07:12:01.299323 2014] [:error] [pid 12118] [client 78.185.112.9:11033] mod_wsgi (pid=12118): Target WSGI script '/home/talehouse.wsgi' cannot be loaded as Python module.
[Sat Jul 05 07:12:01.299393 2014] [:error] [pid 12118] [client 78.185.112.9:11033] mod_wsgi (pid=12118): Exception occurred processing WSGI script '/home/talehouse.wsgi'.
[Sat Jul 05 07:12:01.299415 2014] [:error] [pid 12118] [client 78.185.112.9:11033] Traceback (most recent call last):
[Sat Jul 05 07:12:01.299443 2014] [:error] [pid 12118] [client 78.185.112.9:11033]   File "/home/talehouse.wsgi", line 13, in <module>
[Sat Jul 05 07:12:01.299523 2014] [:error] [pid 12118] [client 78.185.112.9:11033]     execfile(activate_env, dict(__file__=activate_env))
[Sat Jul 05 07:12:01.299550 2014] [:error] [pid 12118] [client 78.185.112.9:11033] IOError: [Errno 13] Permission denied: '/root/env/bin/activate_this.py'
[Sat Jul 05 07:13:13.208003 2014] [:error] [pid 12119] [client 78.185.112.9:11047] mod_wsgi (pid=12119): Target WSGI script '/home/talehouse.wsgi' cannot be loaded as Python module.
[Sat Jul 05 07:13:13.208077 2014] [:error] [pid 12119] [client 78.185.112.9:11047] mod_wsgi (pid=12119): Exception occurred processing WSGI script '/home/talehouse.wsgi'.
[Sat Jul 05 07:13:13.208113 2014] [:error] [pid 12119] [client 78.185.112.9:11047] Traceback (most recent call last):
[Sat Jul 05 07:13:13.208153 2014] [:error] [pid 12119] [client 78.185.112.9:11047]   File "/home/talehouse.wsgi", line 13, in <module>
[Sat Jul 05 07:13:13.208280 2014] [:error] [pid 12119] [client 78.185.112.9:11047]     execfile(activate_env, dict(__file__=activate_env))
[Sat Jul 05 07:13:13.208324 2014] [:error] [pid 12119] [client 78.185.112.9:11047] IOError: [Errno 13] Permission denied: '/root/env/bin/activate_this.py'
[Sat Jul 05 07:13:13.741671 2014] [:error] [pid 12121] [client 78.185.112.9:11046] mod_wsgi (pid=12121): Target WSGI script '/home/talehouse.wsgi' cannot be loaded as Python module.
[Sat Jul 05 07:13:13.741750 2014] [:error] [pid 12121] [client 78.185.112.9:11046] mod_wsgi (pid=12121): Exception occurred processing WSGI script '/home/talehouse.wsgi'.
[Sat Jul 05 07:13:13.741785 2014] [:error] [pid 12121] [client 78.185.112.9:11046] Traceback (most recent call last):
[Sat Jul 05 07:13:13.741831 2014] [:error] [pid 12121] [client 78.185.112.9:11046]   File "/home/talehouse.wsgi", line 13, in <module>
[Sat Jul 05 07:13:13.741949 2014] [:error] [pid 12121] [client 78.185.112.9:11046]     execfile(activate_env, dict(__file__=activate_env))
[Sat Jul 05 07:13:13.742003 2014] [:error] [pid 12121] [client 78.185.112.9:11046] IOError: [Errno 13] Permission denied: '/root/env/bin/activate_this.py'
[Sat Jul 05 07:16:12.291832 2014] [:error] [pid 12173] [client 78.185.112.9:11297] mod_wsgi (pid=12173): Target WSGI script '/home/talehouse.wsgi' cannot be loaded as Python module.
[Sat Jul 05 07:16:12.291931 2014] [:error] [pid 12173] [client 78.185.112.9:11297] mod_wsgi (pid=12173): Exception occurred processing WSGI script '/home/talehouse.wsgi'.
[Sat Jul 05 07:16:12.291966 2014] [:error] [pid 12173] [client 78.185.112.9:11297] Traceback (most recent call last):
[Sat Jul 05 07:16:12.292015 2014] [:error] [pid 12173] [client 78.185.112.9:11297]   File "/home/talehouse.wsgi", line 13, in <module>
[Sat Jul 05 07:16:12.292156 2014] [:error] [pid 12173] [client 78.185.112.9:11297]     execfile(activate_env, dict(__file__=activate_env))
[Sat Jul 05 07:16:12.292205 2014] [:error] [pid 12173] [client 78.185.112.9:11297] IOError: [Errno 13] Permission denied: '/root/env/bin/activate_this.py'
[Sat Jul 05 07:16:12.838025 2014] [:error] [pid 12174] [client 78.185.112.9:11298] mod_wsgi (pid=12174): Target WSGI script '/home/talehouse.wsgi' cannot be loaded as Python module.
[Sat Jul 05 07:16:12.838099 2014] [:error] [pid 12174] [client 78.185.112.9:11298] mod_wsgi (pid=12174): Exception occurred processing WSGI script '/home/talehouse.wsgi'.
[Sat Jul 05 07:16:12.838123 2014] [:error] [pid 12174] [client 78.185.112.9:11298] Traceback (most recent call last):
[Sat Jul 05 07:16:12.838153 2014] [:error] [pid 12174] [client 78.185.112.9:11298]   File "/home/talehouse.wsgi", line 13, in <module>
[Sat Jul 05 07:16:12.838235 2014] [:error] [pid 12174] [client 78.185.112.9:11298]     execfile(activate_env, dict(__file__=activate_env))
[Sat Jul 05 07:16:12.838263 2014] [:error] [pid 12174] [client 78.185.112.9:11298] IOError: [Errno 13] Permission denied: '/root/env/bin/activate_this.py'
[Sat Jul 05 07:24:07.921688 2014] [:error] [pid 12286] [client 78.185.112.9:12025] mod_wsgi (pid=12286): Exception occurred processing WSGI script '/home/talehouse.wsgi'.
[Sat Jul 05 07:24:07.921757 2014] [:error] [pid 12286] [client 78.185.112.9:12025] Traceback (most recent call last):
[Sat Jul 05 07:24:07.921783 2014] [:error] [pid 12286] [client 78.185.112.9:12025]   File "/home/env/lib/python2.7/site-packages/django/core/handlers/wsgi.py", line 187, in __call__
[Sat Jul 05 07:24:07.922187 2014] [:error] [pid 12286] [client 78.185.112.9:12025]     self.load_middleware()
[Sat Jul 05 07:24:07.922208 2014] [:error] [pid 12286] [client 78.185.112.9:12025]   File "/home/env/lib/python2.7/site-packages/django/core/handlers/base.py", line 44, in load_middleware
[Sat Jul 05 07:24:07.922549 2014] [:error] [pid 12286] [client 78.185.112.9:12025]     for middleware_path in settings.MIDDLEWARE_CLASSES:
[Sat Jul 05 07:24:07.922615 2014] [:error] [pid 12286] [client 78.185.112.9:12025]   File "/home/env/lib/python2.7/site-packages/django/conf/__init__.py", line 54, in __getattr__
[Sat Jul 05 07:24:07.922925 2014] [:error] [pid 12286] [client 78.185.112.9:12025]     self._setup(name)
[Sat Jul 05 07:24:07.922945 2014] [:error] [pid 12286] [client 78.185.112.9:12025]   File "/home/env/lib/python2.7/site-packages/django/conf/__init__.py", line 49, in _setup
[Sat Jul 05 07:24:07.922972 2014] [:error] [pid 12286] [client 78.185.112.9:12025]     self._wrapped = Settings(settings_module)
[Sat Jul 05 07:24:07.922986 2014] [:error] [pid 12286] [client 78.185.112.9:12025]   File "/home/env/lib/python2.7/site-packages/django/conf/__init__.py", line 132, in __init__
[Sat Jul 05 07:24:07.923013 2014] [:error] [pid 12286] [client 78.185.112.9:12025]     % (self.SETTINGS_MODULE, e)
[Sat Jul 05 07:24:07.923046 2014] [:error] [pid 12286] [client 78.185.112.9:12025] ImportError: Could not import settings 'talehouse.settings' (Is it on sys.path? Is there an import error in the settings file?): No module named talehouse.settings
[Sat Jul 05 07:24:08.557843 2014] [:error] [pid 12284] [client 78.185.112.9:12024] mod_wsgi (pid=12284): Exception occurred processing WSGI script '/home/talehouse.wsgi'.
[Sat Jul 05 07:24:08.557919 2014] [:error] [pid 12284] [client 78.185.112.9:12024] Traceback (most recent call last):
[Sat Jul 05 07:24:08.557945 2014] [:error] [pid 12284] [client 78.185.112.9:12024]   File "/home/env/lib/python2.7/site-packages/django/core/handlers/wsgi.py", line 187, in __call__
[Sat Jul 05 07:24:08.558075 2014] [:error] [pid 12284] [client 78.185.112.9:12024]     self.load_middleware()
[Sat Jul 05 07:24:08.558096 2014] [:error] [pid 12284] [client 78.185.112.9:12024]   File "/home/env/lib/python2.7/site-packages/django/core/handlers/base.py", line 44, in load_middleware
[Sat Jul 05 07:24:08.558238 2014] [:error] [pid 12284] [client 78.185.112.9:12024]     for middleware_path in settings.MIDDLEWARE_CLASSES:
[Sat Jul 05 07:24:08.558259 2014] [:error] [pid 12284] [client 78.185.112.9:12024]   File "/home/env/lib/python2.7/site-packages/django/conf/__init__.py", line 54, in __getattr__
[Sat Jul 05 07:24:08.558391 2014] [:error] [pid 12284] [client 78.185.112.9:12024]     self._setup(name)
[Sat Jul 05 07:24:08.558409 2014] [:error] [pid 12284] [client 78.185.112.9:12024]   File "/home/env/lib/python2.7/site-packages/django/conf/__init__.py", line 49, in _setup
[Sat Jul 05 07:24:08.558435 2014] [:error] [pid 12284] [client 78.185.112.9:12024]     self._wrapped = Settings(settings_module)
[Sat Jul 05 07:24:08.558449 2014] [:error] [pid 12284] [client 78.185.112.9:12024]   File "/home/env/lib/python2.7/site-packages/django/conf/__init__.py", line 132, in __init__
[Sat Jul 05 07:24:08.558479 2014] [:error] [pid 12284] [client 78.185.112.9:12024]     % (self.SETTINGS_MODULE, e)
[Sat Jul 05 07:24:08.558534 2014] [:error] [pid 12284] [client 78.185.112.9:12024] ImportError: Could not import settings 'talehouse.settings' (Is it on sys.path? Is there an import error in the settings file?): No module named talehouse.settings
